Workbook
Name NativeTimeline_Order_Date: #N/A
Name Slicer_Category: #N/A
Name Slicer_Quarter: #N/A
Name Slicer_Region: #N/A
Name Slicer_Salesperson: #N/A

Sheet DASHBOARD
A1: SALES PERFORMANCE DASHBOARD
A3: FY 2025 | Sales, Profitability & Performance Analysis
A5: Total Sales | C5: Total Profit | E5: Profit Margin | G5: Total Orders | I5: Total Quantity | K5: Average Order Value
A9: =PIVOT_ANALYSIS!A4 -> 10575097 | C9: =PIVOT_ANALYSIS!C4 -> 1429605.6 | E9: =PIVOT_ANALYSIS!E4 -> 0.13518605 | G9: =PIVOT_ANALYSIS!G4 -> 500 | I9: =PIVOT_ANALYSIS!I4 -> 2728 | K9: =PIVOT_ANALYSIS!K4 -> 21150.194
H97: Key Analysis
H99: Insight 1 — Overall performance
H101: ₹10.58M in sales generated ₹1.43M profit, resulting in a 13.52% overall profit margin.
H103: Insight 2 — Category concentration
H105: Technology is the dominant category, contributing approximately 74% of total sales.
H107: Insight 3 — Regional leader
H109: South is the strongest region by both sales and profit, generating approximately ₹2.93M sales and ₹424K profit.
H111: Insight 4 — Discount risk
H113: 20% discount transactions generated the lowest total profit among the five discount levels.
H115: Insight 5 — Loss monitoring
H117: 11 of 500 transactions were loss-making; all occurred at the 20% discount level.

Sheet RAW_DATA
A1: Order ID | B1: Order Date | C1: Customer Name | D1: Region | E1: State | F1: Category | G1: Sub-Category | H1: Product | I1: Quantity | J1: Sales | K1: Discount | L1: Profit | M1: Salesperson | N1: Year | O1: Month No. | P1: Month | Q1: Quarter | R1: Profit Margin | S1: Discount Amount | T1: Profitabilty Status
A2: ORD1002 | B2: 45973 | C2: Customer 20 | D2: South | E2: Tamil Nadu | F2: Office Supplies | G2: Storage | H2: Storage Box | I2: 9 | J2: 2820.84 | K2: 0.2 | L2: -0.98 | M2: Sales Rep 3 | N2: =YEAR(SALES_DATA[[#This Row],[Order Date]]) -> 2025 | O2: =MONTH(SALES_DATA[[#This Row],[Order Date]]) -> 11 | P2: =TEXT(SALES_DATA[[#This Row],[Order Date]],"mmm") -> Nov | Q2: ="Q"&ROUNDUP(MONTH(SALES_DATA[[#This Row],[Order Date]])/3,0) -> Q4 | R2: =IFERROR(SALES_DATA[[#This Row],[Profit]]/SALES_DATA[[#This Row],[Sales]],0) -> -0.00034741425 | S2: =SALES_DATA[[#This Row],[Sales]]*SALES_DATA[[#This Row],[Discount]] -> 564.168 | T2: =IF(SALES_DATA[[#This Row],[Profit]]<0,"Loss","Profit") -> Loss
A3: ORD1003 | B3: 45795 | C3: Customer 27 | D3: North | E3: Punjab | F3: Furniture | G3: Bookcases | H3: Bookcase | I3: 9 | J3: 27748.73 | K3: 0.15 | L3: 4802.16 | M3: Sales Rep 8 | N3: =YEAR(SALES_DATA[[#This Row],[Order Date]]) -> 2025 | O3: =MONTH(SALES_DATA[[#This Row],[Order Date]]) -> 5 | P3: =TEXT(SALES_DATA[[#This Row],[Order Date]],"mmm") -> May | Q3: ="Q"&ROUNDUP(MONTH(SALES_DATA[[#This Row],[Order Date]])/3,0) -> Q2 | R3: =IFERROR(SALES_DATA[[#This Row],[Profit]]/SALES_DATA[[#This Row],[Sales]],0) -> 0.17305873 | S3: =SALES_DATA[[#This Row],[Sales]]*SALES_DATA[[#This Row],[Discount]] -> 4162.3095 | T3: =IF(SALES_DATA[[#This Row],[Profit]]<0,"Loss","Profit") -> Profit
A4: ORD1004 | B4: 45923 | C4: Customer 86 | D4: East | E4: Odisha | F4: Furniture | G4: Tables | H4: Study Table | I4: 10 | J4: 31601.25 | K4: 0.15 | L4: 4175.7 | M4: Sales Rep 8 | N4: =YEAR(SALES_DATA[[#This Row],[Order Date]]) -> 2025 | O4: =MONTH(SALES_DATA[[#This Row],[Order Date]]) -> 9 | P4: =TEXT(SALES_DATA[[#This Row],[Order Date]],"mmm") -> Sep | Q4: ="Q"&ROUNDUP(MONTH(SALES_DATA[[#This Row],[Order Date]])/3,0) -> Q3 | R4: =IFERROR(SALES_DATA[[#This Row],[Profit]]/SALES_DATA[[#This Row],[Sales]],0) -> 0.13213718 | S4: =SALES_DATA[[#This Row],[Sales]]*SALES_DATA[[#This Row],[Discount]] -> 4740.1875 | T4: =IF(SALES_DATA[[#This Row],[Profit]]<0,"Loss","Profit") -> Profit
A5: ORD1005 | B5: 45757 | C5: Customer 14 | D5: North | E5: Delhi | F5: Office Supplies | G5: Binders | H5: Binder | I5: 3 | J5: 1165.55 | K5: 0 | L5: 125.98 | M5: Sales Rep 4 | N5: =YEAR(SALES_DATA[[#This Row],[Order Date]]) -> 2025 | O5: =MONTH(SALES_DATA[[#This Row],[Order Date]]) -> 4 | P5: =TEXT(SALES_DATA[[#This Row],[Order Date]],"mmm") -> Apr | Q5: ="Q"&ROUNDUP(MONTH(SALES_DATA[[#This Row],[Order Date]])/3,0) -> Q2 | R5: =IFERROR(SALES_DATA[[#This Row],[Profit]]/SALES_DATA[[#This Row],[Sales]],0) -> 0.10808631 | S5: =SALES_DATA[[#This Row],[Sales]]*SALES_DATA[[#This Row],[Discount]] -> 0 | T5: =IF(SALES_DATA[[#This Row],[Profit]]<0,"Loss","Profit") -> Profit
A6: ORD1006 | B6: 45850 | C6: Customer 57 | D6: West | E6: Gujarat | F6: Furniture | G6: Chairs | H6: Office Chair | I6: 2 | J6: 5647.68 | K6: 0 | L6: 700.62 | M6: Sales Rep 7 | N6: =YEAR(SALES_DATA[[#This Row],[Order Date]]) -> 2025 | O6: =MONTH(SALES_DATA[[#This Row],[Order Date]]) -> 7 | P6: =TEXT(SALES_DATA[[#This Row],[Order Date]],"mmm") -> Jul | Q6: ="Q"&ROUNDUP(MONTH(SALES_DATA[[#This Row],[Order Date]])/3,0) -> Q3 | R6: =IFERROR(SALES_DATA[[#This Row],[Profit]]/SALES_DATA[[#This Row],[Sales]],0) -> 0.12405448 | S6: =SALES_DATA[[#This Row],[Sales]]*SALES_DATA[[#This Row],[Discount]] -> 0 | T6: =IF(SALES_DATA[[#This Row],[Profit]]<0,"Loss","Profit") -> Profit
A7: ORD1007 | B7: 45672 | C7: Customer 52 | D7: North | E7: Punjab | F7: Furniture | G7: Chairs | H7: Office Chair | I7: 9 | J7: 18789.32 | K7: 0.1 | L7: 4079.37 | M7: Sales Rep 10 | N7: =YEAR(SALES_DATA[[#This Row],[Order Date]]) -> 2025 | O7: =MONTH(SALES_DATA[[#This Row],[Order Date]]) -> 1 | P7: =TEXT(SALES_DATA[[#This Row],[Order Date]],"mmm") -> Jan | Q7: ="Q"&ROUNDUP(MONTH(SALES_DATA[[#This Row],[Order Date]])/3,0) -> Q1 | R7: =IFERROR(SALES_DATA[[#This Row],[Profit]]/SALES_DATA[[#This Row],[Sales]],0) -> 0.2171111 | S7: =SALES_DATA[[#This Row],[Sales]]*SALES_DATA[[#This Row],[Discount]] -> 1878.932 | T7: =IF(SALES_DATA[[#This Row],[Profit]]<0,"Loss","Profit") -> Profit
A8: ORD1008 | B8: 45793 | C8: Customer 69 | D8: South | E8: Tamil Nadu | F8: Furniture | G8: Chairs | H8: Office Chair | I8: 5 | J8: 15568.74 | K8: 0.05 | L8: 1689.71 | M8: Sales Rep 1 | N8: =YEAR(SALES_DATA[[#This Row],[Order Date]]) -> 2025 | O8: =MONTH(SALES_DATA[[#This Row],[Order Date]]) -> 5 | P8: =TEXT(SALES_DATA[[#This Row],[Order Date]],"mmm") -> May | Q8: ="Q"&ROUNDUP(MONTH(SALES_DATA[[#This Row],[Order Date]])/3,0) -> Q2 | R8: =IFERROR(SALES_DATA[[#This Row],[Profit]]/SALES_DATA[[#This Row],[Sales]],0) -> 0.10853223 | S8: =SALES_DATA[[#This Row],[Sales]]*SALES_DATA[[#This Row],[Discount]] -> 778.437 | T8: =IF(SALES_DATA[[#This Row],[Profit]]<0,"Loss","Profit") -> Profit
A9: ORD1009 | B9: 45887 | C9: Customer 64 | D9: West | E9: Maharashtra | F9: Technology | G9: Accessories | H9: Mouse | I9: 8 | J9: 74331.69 | K9: 0 | L9: 7989.84 | M9: Sales Rep 4 | N9: =YEAR(SALES_DATA[[#This Row],[Order Date]]) -> 2025 | O9: =MONTH(SALES_DATA[[#This Row],[Order Date]]) -> 8 | P9: =TEXT(SALES_DATA[[#This Row],[Order Date]],"mmm") -> Aug | Q9: ="Q"&ROUNDUP(MONTH(SALES_DATA[[#This Row],[Order Date]])/3,0) -> Q3 | R9: =IFERROR(SALES_DATA[[#This Row],[Profit]]/SALES_DATA[[#This Row],[Sales]],0) -> 0.10748901 | S9: =SALES_DATA[[#This Row],[Sales]]*SALES_DATA[[#This Row],[Discount]] -> 0 | T9: =IF(SALES_DATA[[#This Row],[Profit]]<0,"Loss","Profit") -> Profit
A10: ORD1010 | B10: 45727 | C10: Customer 40 | D10: North | E10: Punjab | F10: Furniture | G10: Tables | H10: Study Table | I10: 2 | J10: 4470.06 | K10: 0.15 | L10: 174.54 | M10: Sales Rep 10 | N10: =YEAR(SALES_DATA[[#This Row],[Order Date]]) -> 2025 | O10: =MONTH(SALES_DATA[[#This Row],[Order Date]]) -> 3 | P10: =TEXT(SALES_DATA[[#This Row],[Order Date]],"mmm") -> Mar | Q10: ="Q"&ROUNDUP(MONTH(SALES_DATA[[#This Row],[Order Date]])/3,0) -> Q1 | R10: =IFERROR(SALES_DATA[[#This Row],[Profit]]/SALES_DATA[[#This Row],[Sales]],0) -> 0.039046456 | S10: =SALES_DATA[[#This Row],[Sales]]*SALES_DATA[[#This Row],[Discount]] -> 670.509 | T10: =IF(SALES_DATA[[#This Row],[Profit]]<0,"Loss","Profit") -> Profit
A11: ORD1011 | B11: 45934 | C11: Customer 20 | D11: West | E11: Maharashtra | F11: Furniture | G11: Bookcases | H11: Bookcase | I11: 5 | J11: 15126.71 | K11: 0.05 | L11: 1305.19 | M11: Sales Rep 4 | N11: =YEAR(SALES_DATA[[#This Row],[Order Date]]) -> 2025 | O11: =MONTH(SALES_DATA[[#This Row],[Order Date]]) -> 10 | P11: =TEXT(SALES_DATA[[#This Row],[Order Date]],"mmm") -> Oct | Q11: ="Q"&ROUNDUP(MONTH(SALES_DATA[[#This Row],[Order Date]])/3,0) -> Q4 | R11: =IFERROR(SALES_DATA[[#This Row],[Profit]]/SALES_DATA[[#This Row],[Sales]],0) -> 0.086283799 | S11: =SALES_DATA[[#This Row],[Sales]]*SALES_DATA[[#This Row],[Discount]] -> 756.3355 | T11: =IF(SALES_DATA[[#This Row],[Profit]]<0,"Loss","Profit") -> Profit
A12: ORD1012 | B12: 45747 | C12: Customer 100 | D12: North | E12: Punjab | F12: Office Supplies | G12: Storage | H12: Storage Box | I12: 8 | J12: 3098.4 | K12: 0.15 | L12: 658.61 | M12: Sales Rep 6 | N12: =YEAR(SALES_DATA[[#This Row],[Order Date]]) -> 2025 | O12: =MONTH(SALES_DATA[[#This Row],[Order Date]]) -> 3 | P12: =TEXT(SALES_DATA[[#This Row],[Order Date]],"mmm") -> Mar | Q12: ="Q"&ROUNDUP(MONTH(SALES_DATA[[#This Row],[Order Date]])/3,0) -> Q1 | R12: =IFERROR(SALES_DATA[[#This Row],[Profit]]/SALES_DATA[[#This Row],[Sales]],0) -> 0.21256455 | S12: =SALES_DATA[[#This Row],[Sales]]*SALES_DATA[[#This Row],[Discount]] -> 464.76 | T12: =IF(SALES_DATA[[#This Row],[Profit]]<0,"Loss","Profit") -> Profit
A13: ORD1013 | B13: 45970 | C13: Customer 92 | D13: South | E13: Karnataka | F13: Technology | G13: Phones | H13: Smartphone | I13: 10 | J13: 73428.46 | K13: 0.05 | L13: 9863.21 | M13: Sales Rep 7 | N13: =YEAR(SALES_DATA[[#This Row],[Order Date]]) -> 2025 | O13: =MONTH(SALES_DATA[[#This Row],[Order Date]]) -> 11 | P13: =TEXT(SALES_DATA[[#This Row],[Order Date]],"mmm") -> Nov | Q13: ="Q"&ROUNDUP(MONTH(SALES_DATA[[#This Row],[Order Date]])/3,0) -> Q4 | R13: =IFERROR(SALES_DATA[[#This Row],[Profit]]/SALES_DATA[[#This Row],[Sales]],0) -> 0.13432408 | S13: =SALES_DATA[[#This Row],[Sales]]*SALES_DATA[[#This Row],[Discount]] -> 3671.423 | T13: =IF(SALES_DATA[[#This Row],[Profit]]<0,"Loss","Profit") -> Profit
... A501: ORD1501 | B501: 46000 | C501: Customer 41 | D501: South | E501: Tamil Nadu | F501: Technology | G501: Laptops | H501: Laptop | I501: 9 | J501: 61616.78 | K501: 0.1 | L501: 11206.32 | M501: Sales Rep 9 | N501: =YEAR(SALES_DATA[[#This Row],[Order Date]]) -> 2025 | O501: =MONTH(SALES_DATA[[#This Row],[Order Date]]) -> 12 | P501: =TEXT(SALES_DATA[[#This Row],[Order Date]],"mmm") -> Dec | Q501: ="Q"&ROUNDUP(MONTH(SALES_DATA[[#This Row],[Order Date]])/3,0) -> Q4 | R501: =IFERROR(SALES_DATA[[#This Row],[Profit]]/SALES_DATA[[#This Row],[Sales]],0) -> 0.18187124 | S501: =SALES_DATA[[#This Row],[Sales]]*SALES_DATA[[#This Row],[Discount]] -> 6161.678 | T501: =IF(SALES_DATA[[#This Row],[Profit]]<0,"Loss","Profit") -> Profit

Sheet PIVOT_ANALYSIS
A1: SALES KPI VALIDATION
A3: TOTAL SALES | C3: Total Profit | E3: Profit Margin | G3: Total Orders | I3: Total Quantity | K3: Average Order Value
A4: =SUM(SALES_DATA[Sales]) -> 10575097 | C4: =SUM(SALES_DATA[Profit]) -> 1429605.6 | E4: =SUM(SALES_DATA[Profit])/SUM(SALES_DATA[Sales]) -> 0.13518605 | G4: =COUNTA(SALES_DATA[Order ID]) -> 500 | I4: =SUM(SALES_DATA[Quantity]) -> 2728 | K4: =SUM(SALES_DATA[Sales])/COUNTA(SALES_DATA[Order ID]) -> 21150.194
B7: Monthly Sales & Profit | I7: Regional Performance
A8: MONTH | B8: TOTAL SALES | G8: REGION | H8: Total Profit
A9: Jan | B9: 908368.04 | G9: East | H9: 322675.76
A10: Feb | B10: 589275.36 | G10: North | H10: 315725.73
A11: Mar | B11: 472684.79 | G11: South | H11: 423814.3
A12: Apr | B12: 773322.37 | G12: West | H12: 367389.82
A13: May | B13: 1072785.1 | G13: Grand Total | H13: 1429605.6
A14: Jun | B14: 802036.55
A15: Jul | B15: 970821.05
A16: Aug | B16: 768520.66
A17: Sep | B17: 921081.01
A18: Oct | B18: 1307874.5
A19: Nov | B19: 1128940.3
A20: Dec | B20: 859387.24
A21: Grand Total | B21: 10575097
B24: Category Performance | H24: Sub-Category Performance
A25: Category | B25: Total Profit | G25: Sub Category | H25: Total Sales | I25: Total Profit | J25: Total Quantity
A26: Furniture | B26: 346478 | G26: Accessories | H26: 2737523 | I26: 363396.54 | J26: 325
A27: Office Supplies | B27: 38963.94 | G27: Phones | H27: 2584679.1 | I27: 355164.64 | J27: 304
A28: Technology | B28: 1044163.7 | G28: Laptops | H28: 2453944.5 | I28: 325602.49 | J28: 293
A29: Grand Total | B29: 1429605.6 | G29: Tables | H29: 973809.34 | I29: 131455.05 | J29: 360
G30: Bookcases | H30: 863221.26 | I30: 124677.14 | J30: 325
G31: Chairs | H31: 695900.87 | I31: 90345.81 | J31: 269
G32: Storage | H32: 102387.12 | I32: 15945.7 | J32: 333
G33: Binders | H33: 97126.51 | I33: 13537.98 | J33: 302
G34: Paper | H34: 66505.28 | I34: 9480.26 | J34: 217
G35: Grand Total | H35: 10575097 | I35: 1429605.6 | J35: 2728
B39: Product Performance | H39: SalesPerson Performance
A40: Product | B40: Total Sales | F40: SalesPerson | G40: Total Sales
A41: A4 Paper | B41: 66505.28 | F41: Sales Rep 10 | G41: 744903.53
A42: Binder | B42: 97126.51 | F42: Sales Rep 4 | G42: 779655.63
A43: Storage Box | B43: 102387.12 | F43: Sales Rep 5 | G43: 781705.66
A44: Office Chair | B44: 695900.87 | F44: Sales Rep 6 | G44: 933214.56
A45: Bookcase | B45: 863221.26 | F45: Sales Rep 3 | G45: 1003276.3
A46: Study Table | B46: 973809.34 | F46: Sales Rep 8 | G46: 1095720.5
A47: Laptop | B47: 2453944.5 | F47: Sales Rep 1 | G47: 1119295.2
A48: Smartphone | B48: 2584679.1 | F48: Sales Rep 7 | G48: 1348552.5
...

Sheet Profit and Loss
A1: Profitabilty Status | B1: Loss
A3: Row Labels | B3: Sum of Sales | C3: Sum of Profit | D3: Sum of Discount | E3: Count of Order ID
A4: East | B4: 14525.39 | C4: -256.89 | D4: 0.4 | E4: 2
A5: Office Chair | B5: 14248.1 | C5: -254.38 | D5: 0.2 | E5: 1
A6: Storage Box | B6: 277.29 | C6: -2.51 | D6: 0.2 | E6: 1
A7: North | B7: 121376.82 | C7: -671.63 | D7: 0.6 | E7: 3
A8: Binder | B8: 388.38 | C8: -3.56 | D8: 0.2 | E8: 1
A9: Laptop | B9: 39182.02 | C9: -353.74 | D9: 0.2 | E9: 1
A10: Smartphone | B10: 81806.42 | C10: -314.33 | D10: 0.2 | E10: 1
A11: South | B11: 28500.29 | C11: -336.38 | D11: 0.8 | E11: 4
A12: Mouse | B12: 18990.14 | C12: -305.48 | D12: 0.2 | E12: 1
A13: Office Chair | B13: 4285.13 | C13: -0.96 | D13: 0.2 | E13: 1
A14: Storage Box | B14: 2820.84 | C14: -0.98 | D14: 0.2 | E14: 1
A15: Study Table | B15: 2404.18 | C15: -28.96 | D15: 0.2 | E15: 1
... A19: Grand Total | B19: 245751.17 | C19: -2299.92 | D19: 2.2 | E19: 11
